{"uuid": "6d7c339a-c4da-4d69-92a7-e7dceb3ab6d1", "children": ["eb8397fe-afdc-49a0-bedf-4edd5e366855"], "befores": [{"name": "browser", "status": "broken", "statusDetails": {"message": "selenium.common.exceptions.WebDriverException: Message: New session attempts retry count exceeded\n\n", "trace": "  File \"/home/pavel/qa/selenium_logs/venv/lib/python3.8/site-packages/pluggy/_callers.py\", line 39, in _multicall\n    res = hook_impl.function(*args)\n  File \"/home/pavel/qa/selenium_logs/venv/lib/python3.8/site-packages/_pytest/fixtures.py\", line 1126, in pytest_fixture_setup\n    result = call_fixture_func(fixturefunc, request, kwargs)\n  File \"/home/pavel/qa/selenium_logs/venv/lib/python3.8/site-packages/_pytest/fixtures.py\", line 932, in call_fixture_func\n    fixture_result = fixturefunc(**kwargs)\n  File \"/home/pavel/qa/selenium_logs/conftest.py\", line 66, in browser\n    driver = webdriver.Remote(command_executor=f\"http://{executor}:4444/wd/hub\",\n  File \"/home/pavel/qa/selenium_logs/venv/lib/python3.8/site-packages/selenium/webdriver/remote/webdriver.py\", line 157, in __init__\n    self.start_session(capabilities, browser_profile)\n  File \"/home/pavel/qa/selenium_logs/venv/lib/python3.8/site-packages/selenium/webdriver/remote/webdriver.py\", line 252, in start_session\n    response = self.execute(Command.NEW_SESSION, parameters)\n  File \"/home/pavel/qa/selenium_logs/venv/lib/python3.8/site-packages/selenium/webdriver/remote/webdriver.py\", line 321, in execute\n    self.error_handler.check_response(response)\n  File \"/home/pavel/qa/selenium_logs/venv/lib/python3.8/site-packages/selenium/webdriver/remote/errorhandler.py\", line 242, in check_response\n    raise exception_class(message, screen, stacktrace)\n"}, "start": 1634368217731, "stop": 1634368637652}], "start": 1634368217731, "stop": 1634368638366}